<mujoco model="gen3">
    <compiler angle="radian" meshdir="/home/user/mj-kdl-wrapper/assets/kinova_gen3/assets"/>
    <option integrator="implicitfast"/>
    <default>
        <default class="visual">
            <geom type="mesh" contype="0" conaffinity="0" group="2" rgba="0.75294 0.75294 0.75294 1"/>
        </default>
        <default class="collision">
            <geom type="mesh" group="3"/>
        </default>
        <default class="large_actuator">
            <position kp="2000" kv="100" forcerange="-105 105"/>
        </default>
        <default class="small_actuator">
            <position kp="500" kv="50" forcerange="-52 52"/>
        </default>
        <site size="0.001" rgba="0.5 0.5 0.5 0.3" group="4"/>
        <default class="g_2f85">
            <mesh scale="0.001 0.001 0.001"/>
            <general biastype="affine"/>
            <joint axis="0 0 1"/>
            <default class="g_driver">
                <joint range="0 0.9" armature="0.005" damping="0.1" solimplimit="0.95 0.99 0.001" solreflimit="0.005 1"/>
            </default>
            <default class="g_follower">
                <joint range="-0.872664 0.9" armature="0.001" solimplimit="0.95 0.99 0.001" solreflimit="0.005 1"/>
            </default>
            <default class="g_spring_link">
                <joint range="-0.29670597283 0.9" armature="0.001" stiffness="0.05" springref="2.62" damping="0.00125"/>
            </default>
            <default class="g_coupler">
                <joint range="-1.57 0" armature="0.001" solimplimit="0.95 0.99 0.001" solreflimit="0.005 1"/>
            </default>
            <default class="g_visual">
                <geom type="mesh" contype="0" conaffinity="0" group="2" material="g_black"/>
            </default>
            <default class="g_collision">
                <geom type="mesh" group="3"/>
                <default class="g_pad_box1">
                    <geom mass="1e-6" type="box" pos="0.043258  0 0.12" size="0.002 0.011 0.009375" friction="0.7" solimp="0.95 0.99 0.001" solref="0.004 1" priority="1" rgba="0.55 0.55 0.55 1"/>
                </default>
                <default class="g_pad_box2">
                    <geom mass="1e-6" type="box" pos="0.043258 0 0.13875" size="0.002 0.011 0.009375" friction="0.6" solimp="0.95 0.99 0.001" solref="0.004 1" priority="1" rgba="0.45 0.45 0.45 1"/>
                </default>
            </default>
        </default>
    </default>
    <asset>
        <texture type="skybox" builtin="gradient" rgb1="0.3 0.45 0.65" rgb2="0.65 0.8 0.95" width="200" height="200"/>
        <mesh name="base_link" file="base_link.stl"/>
        <mesh name="shoulder_link" file="shoulder_link.stl"/>
        <mesh name="half_arm_1_link" file="half_arm_1_link.stl"/>
        <mesh name="half_arm_2_link" file="half_arm_2_link.stl"/>
        <mesh name="forearm_link" file="forearm_link.stl"/>
        <mesh name="spherical_wrist_1_link" file="spherical_wrist_1_link.stl"/>
        <mesh name="spherical_wrist_2_link" file="spherical_wrist_2_link.stl"/>
        <mesh name="bracelet_with_vision_link" file="bracelet_with_vision_link.stl"/>
        <material name="g_metal" rgba="0.58 0.58 0.58 1"/>
        <material name="g_silicone" rgba="0.1882 0.1882 0.1882 1"/>
        <material name="g_black" rgba="0.149 0.149 0.149 1"/>
        <mesh file="/home/user/mj-kdl-wrapper/assets/robotiq_2f85_v4/assets/base.stl" name="g_base"/>
        <mesh file="/home/user/mj-kdl-wrapper/assets/robotiq_2f85_v4/assets/base_coupling.stl" name="g_base_coupling"/>
        <mesh file="/home/user/mj-kdl-wrapper/assets/robotiq_2f85_v4/assets/c-a01-85-open.stl" name="g_c-a01-85-open"/>
        <mesh file="/home/user/mj-kdl-wrapper/assets/robotiq_2f85_v4/assets/driver.stl" name="g_driver"/>
        <mesh file="/home/user/mj-kdl-wrapper/assets/robotiq_2f85_v4/assets/coupler.stl" name="g_coupler"/>
        <mesh file="/home/user/mj-kdl-wrapper/assets/robotiq_2f85_v4/assets/spring_link.stl" name="g_spring_link"/>
        <mesh file="/home/user/mj-kdl-wrapper/assets/robotiq_2f85_v4/assets/follower.stl" name="g_follower"/>
        <mesh file="/home/user/mj-kdl-wrapper/assets/robotiq_2f85_v4/assets/tongue.stl" name="g_tongue"/>
        <texture type="2d" name="groundplane" builtin="checker" rgb1="0.2 0.3 0.4" rgb2="0.1 0.2 0.3" width="300" height="300"/>
        <material name="groundplane" texture="groundplane" texrepeat="5 5" reflectance="0.2"/>
    </asset>
    <worldbody>
        <light pos="0 0 4" directional="true"/>
        <geom name="floor" type="plane" material="groundplane" size="5 5 0.05" condim="3"/>
        <body name="base_link">
            <inertial pos="-0.000648 -0.000166 0.084487" quat="0.999294 0.00139618 -0.0118387 0.035636" mass="1.697" diaginertia="0.00462407 0.00449437 0.00207755"/>
            <geom class="visual" mesh="base_link"/>
            <geom class="collision" mesh="base_link"/>
            <body name="shoulder_link" pos="0 0 0.15643" quat="0 1 0 0">
                <inertial pos="-2.3e-05 -0.010364 -0.07336" quat="0.707051 0.0451246 -0.0453544 0.704263" mass="1.3773" diaginertia="0.00488868 0.00457 0.00135132"/>
                <joint name="joint_1"/>
                <geom class="visual" mesh="shoulder_link"/>
                <geom class="collision" mesh="shoulder_link"/>
                <body name="half_arm_1_link" pos="0 0.005375 -0.12838" quat="1 1 0 0">
                    <inertial pos="-4.4e-05 -0.09958 -0.013278" quat="0.482348 0.516286 -0.516862 0.483366" mass="1.1636" diaginertia="0.0113017 0.011088 0.00102532"/>
                    <joint name="joint_2" range="-2.24 2.24"/>
                    <geom class="visual" mesh="half_arm_1_link"/>
                    <geom class="collision" mesh="half_arm_1_link"/>
                    <body name="half_arm_2_link" pos="0 -0.21038 -0.006375" quat="1 -1 0 0">
                        <inertial pos="-4.4e-05 -0.006641 -0.117892" quat="0.706144 0.0213722 -0.0209128 0.707437" mass="1.1636" diaginertia="0.0111633 0.010932 0.00100671"/>
                        <joint name="joint_3"/>
                        <geom class="visual" mesh="half_arm_2_link"/>
                        <geom class="collision" mesh="half_arm_2_link"/>
                        <body name="forearm_link" pos="0 0.006375 -0.21038" quat="1 1 0 0">
                            <inertial pos="-1.8e-05 -0.075478 -0.015006" quat="0.483678 0.515961 -0.515859 0.483455" mass="0.9302" diaginertia="0.00834839 0.008147 0.000598606"/>
                            <joint name="joint_4" range="-2.57 2.57"/>
                            <geom class="visual" mesh="forearm_link"/>
                            <geom class="collision" mesh="forearm_link"/>
                            <body name="spherical_wrist_1_link" pos="0 -0.20843 -0.006375" quat="1 -1 0 0">
                                <inertial pos="1e-06 -0.009432 -0.063883" quat="0.703558 0.0707492 -0.0707492 0.703558" mass="0.6781" diaginertia="0.00165901 0.001596 0.000346988"/>
                                <joint name="joint_5"/>
                                <geom class="visual" mesh="spherical_wrist_1_link"/>
                                <geom class="collision" mesh="spherical_wrist_1_link"/>
                                <body name="spherical_wrist_2_link" pos="0 0.00017505 -0.10593" quat="1 1 0 0">
                                    <inertial pos="1e-06 -0.045483 -0.00965" quat="0.44426 0.550121 -0.550121 0.44426" mass="0.6781" diaginertia="0.00170087 0.001641 0.00035013"/>
                                    <joint name="joint_6" range="-2.09 2.09"/>
                                    <geom class="visual" mesh="spherical_wrist_2_link"/>
                                    <geom class="collision" mesh="spherical_wrist_2_link"/>
                                    <body name="bracelet_link" pos="0 -0.10593 -0.00017505" quat="1 -1 0 0">
                                        <inertial pos="0.000281 0.011402 -0.029798" quat="0.394358 0.596779 -0.577293 0.393789" mass="0.5" diaginertia="0.000657336 0.000587019 0.000320645"/>
                                        <joint name="joint_7"/>
                                        <geom class="visual" mesh="bracelet_with_vision_link"/>
                                        <geom class="collision" mesh="bracelet_with_vision_link"/>
                                        <camera name="wrist" pos="0 -0.05639 -0.058475" quat="0 0 0 1" fovy="41.83792730009236" resolution="640 480"/>
                                        <site name="pinch_site" pos="0 0 -0.061525" quat="0 1 0 0"/>
                                        <body name="g_base" childclass="g_2f85" pos="0.000000 0.000000 -0.061525" quat="0.000000 1.000000 0.000000 0.000000">
                                            <inertial mass="0.777441" pos="0 -2.70394e-05 0.0354675" quat="1 -0.00152849 0 0" diaginertia="0.000260285 0.000225381 0.000152708"/>
                                            <geom class="g_visual" pos="0 0 0.0108" quat="0 0 0 1" mesh="g_base"/>
                                            <geom class="g_visual" pos="0 0 0.004" quat="1 -1 0 0" mesh="g_base_coupling"/>
                                            <geom class="g_visual" pos="0 0 0.0108" quat="1 0 0 0" material="g_metal" mesh="g_c-a01-85-open"/>
                                            <geom class="g_collision" mesh="g_base"/>
                                            <body name="g_left_driver" pos="-0.0306011 0.00475 0.0657045" quat="1 -1 0 0">
                                                <inertial mass="0.00899563" pos="0 0.0177547 0.00107314" quat="0.681301 0.732003 0 0" diaginertia="1.72352e-06 1.60906e-06 3.22006e-07"/>
                                                <joint name="g_left_driver_joint" class="g_driver"/>
                                                <geom class="g_visual" pos="0.0306011 0.0549045 -0.0047" quat="1 1 0 0" material="g_metal" mesh="g_driver"/>
                                                <geom class="g_collision" pos="0.0306011 0.0549045 -0.0047" quat="1 1 0 0" mesh="g_driver"/>
                                                <body name="g_left_coupler" pos="-0.0314249 0.00453223 -0.0102" quat="0 0 0 1">
                                                    <inertial mass="0.0140974" pos="0 0.00301209 0.0232175" quat="0.705636 -0.0455904 0.0455904 0.705636" diaginertia="4.16206e-06 3.52216e-06 8.88131e-07"/>
                                                    <geom class="g_visual" pos="-0.062026 -0.0503723 0.0055" quat="1 -1 0 0" mesh="g_coupler"/>
                                                    <geom class="g_collision" pos="-0.062026 -0.0503723 0.0055" quat="1 -1 0 0" mesh="g_coupler"/>
                                                </body>
                                            </body>
                                            <body name="g_left_spring_link" pos="-0.0127 -0.012 0.07222" quat="1 -1 0 0">
                                                <inertial mass="0.0221642" pos="-8.65005e-09 0.0181624 0.0212658" quat="0.663403 -0.244737 0.244737 0.663403" diaginertia="8.96853e-06 6.71733e-06 2.63931e-06"/>
                                                <joint name="g_left_spring_link_joint" class="g_spring_link"/>
                                                <geom class="g_visual" pos="0.0127 0.06142 0.01205" quat="1 1 0 0" type="mesh" mesh="g_spring_link"/>
                                                <geom class="g_collision" pos="0.0127 0.06142 0.01205" quat="1 1 0 0" type="mesh" mesh="g_spring_link"/>
                                                <body name="g_left_follower" pos="-0.0382079 -0.0425003 0.00295" quat="0 -1 -1.90231e-05 0">
                                                    <inertial mass="0.0125222" pos="0 -0.011046 0.0124786" quat="1 0.1664 0 0" diaginertia="2.67415e-06 2.4559e-06 6.02031e-07"/>
                                                    <joint name="g_left_follower" class="g_follower"/>
                                                    <geom class="g_visual" pos="0.0509079 -0.10392 -0.0091" quat="1 -1 0 0" type="mesh" mesh="g_follower"/>
                                                    <geom class="g_visual" pos="0.0509079 -0.10392 -0.0091" quat="1 -1 0 0" type="mesh" material="g_metal" mesh="g_tongue"/>
                                                    <geom class="g_collision" pos="0.0509079 -0.10392 -0.0091" quat="1 -1 0 0" type="mesh" mesh="g_follower"/>
                                                    <geom class="g_collision" pos="0.0509079 -0.10392 -0.0091" quat="1 -1 0 0" type="mesh" mesh="g_tongue"/>
                                                    <body name="g_left_pad" pos="-0.0377897 -0.103916 -0.0091" quat="1 -1 0 0">
                                                        <geom class="g_pad_box1" name="g_left_pad1"/>
                                                        <geom class="g_pad_box2" name="g_left_pad2"/>
                                                    </body>
                                                </body>
                                            </body>
                                            <body name="g_right_driver" pos="0.0306011 -0.00475 0.0657045" quat="0 0 -1 1">
                                                <inertial mass="0.00899563" pos="2.96931e-12 0.0177547 0.00107314" quat="0.681301 0.732003 0 0" diaginertia="1.72352e-06 1.60906e-06 3.22006e-07"/>
                                                <joint name="g_right_driver_joint" class="g_driver"/>
                                                <geom class="g_visual" pos="0.0306011 0.0549045 -0.0047" quat="1 1 0 0" material="g_metal" mesh="g_driver"/>
                                                <geom class="g_collision" pos="0.0306011 0.0549045 -0.0047" quat="1 1 0 0" mesh="g_driver"/>
                                                <body name="g_right_coupler" pos="-0.0314249 0.00453223 -0.0102" quat="0 0 0 1">
                                                    <inertial mass="0.0140974" pos="0 0.00301209 0.0232175" quat="0.705636 -0.0455904 0.0455904 0.705636" diaginertia="4.16206e-06 3.52216e-06 8.88131e-07"/>
                                                    <geom class="g_visual" pos="-0.062026 -0.0503723 0.0055" quat="1 -1 0 0" mesh="g_coupler"/>
                                                    <geom class="g_collision" pos="-0.062026 -0.0503723 0.0055" quat="1 -1 0 0" mesh="g_coupler"/>
                                                </body>
                                            </body>
                                            <body name="g_right_spring_link" pos="0.0127 0.012 0.07222" quat="0 0 -1 1">
                                                <inertial mass="0.0221642" pos="-8.65005e-09 0.0181624 0.0212658" quat="0.663403 -0.244737 0.244737 0.663403" diaginertia="8.96853e-06 6.71733e-06 2.63931e-06"/>
                                                <joint name="g_right_spring_link_joint" class="g_spring_link"/>
                                                <geom class="g_visual" pos="0.0127 0.06142 0.01205" quat="1 1 0 0" mesh="g_spring_link"/>
                                                <geom class="g_collision" pos="0.0127 0.06142 0.01205" quat="1 1 0 0" mesh="g_spring_link"/>
                                                <body name="g_right_follower" pos="-0.0382079 -0.0425003 0.00295" quat="0 -1 0 0">
                                                    <inertial mass="0.0125222" pos="0 -0.011046 0.0124786" quat="1 0.1664 0 0" diaginertia="2.67415e-06 2.4559e-06 6.02031e-07"/>
                                                    <joint name="g_right_follower_joint" class="g_follower"/>
                                                    <geom class="g_visual" pos="0.0509079 -0.10392 -0.0091" quat="1 -1 0 0" material="g_metal" mesh="g_tongue"/>
                                                    <geom class="g_visual" pos="0.0509079 -0.10392 -0.0091" quat="1 -1 0 0" mesh="g_follower"/>
                                                    <geom class="g_collision" pos="0.0509079 -0.10392 -0.0091" quat="1 -1 0 0" mesh="g_tongue"/>
                                                    <geom class="g_collision" pos="0.0509079 -0.10392 -0.0091" quat="1 -1 0 0" mesh="g_follower"/>
                                                    <body name="g_right_pad" pos="-0.0377897 -0.103916 -0.0091" quat="1 -1 0 0">
                                                        <geom class="g_pad_box1" name="g_right_pad1"/>
                                                        <geom class="g_pad_box2" name="g_right_pad2"/>
                                                    </body>
                                                </body>
                                            </body>
                                        </body>
                                    </body>
                                </body>
                            </body>
                        </body>
                    </body>
                </body>
            </body>
        </body>
    </worldbody>
    <actuator>
        <position class="large_actuator" name="joint_1" joint="joint_1"/>
        <position class="large_actuator" name="joint_2" joint="joint_2" ctrlrange="-2.2497294058206907 2.2497294058206907"/>
        <position class="large_actuator" name="joint_3" joint="joint_3"/>
        <position class="large_actuator" name="joint_4" joint="joint_4" ctrlrange="-2.5795966344476193 2.5795966344476193"/>
        <position class="small_actuator" name="joint_5" joint="joint_5"/>
        <position class="small_actuator" name="joint_6" joint="joint_6" ctrlrange="-2.0996310901491784 2.0996310901491784"/>
        <position class="small_actuator" name="joint_7" joint="joint_7"/>
        <general class="g_2f85" name="g_fingers_actuator" tendon="g_split" forcerange="-5 5" ctrlrange="0 255" gainprm="0.3137255 0 0" biasprm="0 -100 -10"/>
    </actuator>
    <keyframe>
        <key name="home" qpos="0 0.26179939 3.14159265 -2.26892803 0 0.95993109 1.57079633" ctrl="0 0.26179939 3.14159265 -2.26892803 0 0.95993109 1.57079633"/>
        <key name="retract" qpos="0 -0.34906585 3.14159265 -2.54818071 0 -0.87266463 1.57079633" ctrl="0 -0.34906585 3.14159265 -2.54818071 0 -0.87266463 1.57079633"/>
    </keyframe>
    <contact>
        <exclude body1="g_base" body2="g_left_driver"/>
        <exclude body1="g_base" body2="g_right_driver"/>
        <exclude body1="g_base" body2="g_left_spring_link"/>
        <exclude body1="g_base" body2="g_right_spring_link"/>
        <exclude body1="g_right_coupler" body2="g_right_follower"/>
        <exclude body1="g_left_coupler" body2="g_left_follower"/>
        <exclude body1="bracelet_link" body2="g_base"/>
        <exclude body1="bracelet_link" body2="g_left_driver"/>
        <exclude body1="bracelet_link" body2="g_right_driver"/>
        <exclude body1="bracelet_link" body2="g_left_spring_link"/>
        <exclude body1="bracelet_link" body2="g_right_spring_link"/>
        <exclude body1="bracelet_link" body2="g_left_follower"/>
        <exclude body1="bracelet_link" body2="g_right_follower"/>
        <exclude body1="bracelet_link" body2="g_left_coupler"/>
        <exclude body1="bracelet_link" body2="g_right_coupler"/>
        <exclude body1="bracelet_link" body2="g_left_pad"/>
        <exclude body1="bracelet_link" body2="g_right_pad"/>
    </contact>
    <tendon>
        <fixed name="g_split">
            <joint joint="g_right_driver_joint" coef="0.485"/>
            <joint joint="g_left_driver_joint" coef="0.485"/>
        </fixed>
    </tendon>
    <equality>
        <connect anchor="-0.0179014000 -0.0313647800 1.1917850000" body1="g_right_follower" body2="g_right_coupler" solimp="0.95 0.99 0.001" solref="0.005 1"/>
        <connect anchor="-0.0179014000 -0.0313647800 1.1917850000" body1="g_left_follower" body2="g_left_coupler" solimp="0.95 0.99 0.001" solref="0.005 1"/>
        <joint joint1="g_right_driver_joint" joint2="g_left_driver_joint" polycoef="0 1 0 0 0" solimp="0.95 0.99 0.001" solref="0.005 1"/>
    </equality>
</mujoco>
